<?xml version="1.0"?>
<robot name="Self_Balancing_Robot">
    <link name="base_footprint">
        <visual>
            <origin xyz="0 0 0" rpy="0 0 0"/>
            <geometry>
                <box size="0.05 0.05 0.01"/>
            </geometry>
        </visual>
    </link>

    <joint name="base_link_joint" type="floating">
        <origin xyz="0 0 0.05" rpy="0 0 0"/>
        <parent link="base_footprint"/>
        <child link="Chassis"/>
    </joint>

    <link name="Chassis">
        <inertial>
            <origin xyz="0 0 0" rpy="0 0 0"/>
            <mass value="1.0"/>
            <inertia ixx="0.01" iyy="0.01" izz="0.01" 
                     ixy="0.0" ixz="0.0" iyz="0.0"/>
        </inertial>
        <collision>
            <geometry>
                <box size="0.1 0.15 0.05"/>
            </geometry>
            <origin rpy="0 0 0" xyz="0 0 0"/>
        </collision>
        <visual>
            <geometry>
                <mesh filename="meshes/Assem_No_wheelTiny.dae"/>
            </geometry>
            <origin rpy="0 0 0" xyz="-0.05 -0.075 -0.025"/>
        </visual>
    </link>

    <link name="Right_Wheel">
        <inertial>
            <origin xyz="0 0 0" rpy="0 0 0"/>
            <mass value="0.2"/>
            <inertia ixx="0.00025" ixy="0.0" ixz="0.0" 
                     iyy="0.0005" iyz="0.0" izz="0.00025"/>
        </inertial>
        <collision>
            <geometry>
                <cylinder radius="0.07" length="0.03"/>
            </geometry>
            <origin rpy="1.5707963267948966 0 0" xyz="0 0 0"/>
        </collision>
        <visual>
            <geometry>
                <cylinder radius="0.07" length="0.03"/>
            </geometry>
            <origin rpy="1.5707963267948966 0 0" xyz="0 0 0"/>
            <material name="black">
                <color rgba="0 0 0 1"/> <!-- Black color -->
            </material>

        </visual>
    </link>

    <joint name="Right_wheel_Joint" type="continuous">
        <parent link="Chassis"/>
        <child link="Right_Wheel"/>
        <origin rpy="0 0 0" xyz="0 0.10 0.0"/>
        <axis xyz="0 1 0"/>
        <limit effort="5" velocity="10"/>
        <dynamics damping="0.1" friction="0.1"/>
    </joint>

    <link name="Left_Wheel">
        <inertial>
            <origin xyz="0 0 0" rpy="0 0 0"/>
            <mass value="0.2"/>
            <inertia ixx="0.00025" ixy="0.0" ixz="0.0" 
                     iyy="0.0005" iyz="0.0" izz="0.00025"/>
        </inertial>
        <collision>
            <geometry>
                <cylinder radius="0.07" length="0.03"/>
            </geometry>
            <origin rpy="1.5707963267948966 0 0" xyz="0 0 0"/>
        </collision>
        <visual>
            <geometry>
                <cylinder radius="0.07" length="0.03"/>
            </geometry>
            <origin rpy="1.5707963267948966 0 0" xyz="0 0 0"/>
            <material name="black">
                <color rgba="0 0 0 1"/> <!-- Black color -->
            </material>

        </visual>
    </link>

    <joint name="Left_wheel_Joint" type="continuous">
        <parent link="Chassis"/>
        <child link="Left_Wheel"/>
        <origin rpy="0 0 0" xyz="0 -0.079 0.0"/>
        <axis xyz="0 1 0"/>
        <limit effort="5" velocity="10"/>
        <dynamics damping="0.1" friction="0.1"/>
    </joint>
</robot>
